<?xml version="1.0"?>
<robot name="Twizzy">
  <material name="blue">
    <color rgba="0 0 0.8 1"/>
  </material>

  <material name="white">
    <color rgba="1 1 1 1"/>
  </material>

  <material name="red">
    <color rgba="0.8 0 0 1"/>
  </material>


  <link name="base_link">
    <visual>
      <geometry>
        <box size="1.1 0.8 1.15"/>
      </geometry>
      <origin rpy="0 0 0" xyz="0.2 0.0 0.575"/><!--0.3725-->
      <material name="blue"/>
    </visual>
  </link>

  <link name="centre">
  </link>
  <joint name="base_to_centre" type="fixed">
    <parent link="base_link"/>
    <child link="centre"/>
    <origin xyz="0.55 0 0.25"/>
  </joint>

  <link name="bonnet">
    <visual>
      <geometry>
        <box size="0.8 0.8 0.5"/>
      </geometry>
      <origin rpy="0 0 0" xyz="0 0 0"/><!--0.3725-->
      <material name="blue"/>
    </visual>
  </link>
  <joint name="base_to_bonnet" type="fixed">
    <parent link="base_link"/>
    <child link="bonnet"/>
    <origin xyz="1.15 0 0.25"/>
  </joint>

  <link name="velodyne">
    <visual>
      <geometry>
        <cylinder length="0.095" radius="0.08"/>
      </geometry>
      <origin rpy="0 0 0" xyz="0 0 0"/>
      <material name="white"/>
    </visual>
  </link>
  <joint name="base_to_velodyne" type="fixed">
    <parent link="base_link"/>
    <child link="velodyne"/>
    <origin xyz="0 0 1.25"/>
  </joint>

  <link name="imu">
    <visual>
      <geometry>
        <cylinder length="0.05" radius="0.05"/>
      </geometry>
      <origin rpy="0 0 0" xyz="0 0 0"/>
      <material name="white"/>
    </visual>
  </link>

  <joint name="base_to_imu" type="fixed">
    <parent link="velodyne"/>
    <child link="imu"/>
    <origin xyz="-0.019 0.052 -0.035"/>
  </joint>

  <!--WHEELS-->
  <!--WHEELS-->
  <!--WHEELS-->
    <link name="wheel_back_left">
    <visual>
      <geometry>
        <cylinder length="0.13" radius="0.25"/>
      </geometry>
      <origin rpy="0 0 0" xyz="0 0 0"/>
      <material name="white"/>
    </visual>
  </link>

  <joint name="base_to_wheel_back_left" type="continuous">
    <parent link="base_link"/>
    <child link="wheel_back_left"/>
    <origin xyz="-0.35 0.4 0.0" rpy="-1.5707 0 0"/>
    <axis xyz="0 0 1"/>
  </joint>

  <link name="wheel_back_right">
    <visual>
      <geometry>
        <cylinder length="0.13" radius="0.25"/>
      </geometry>
      <origin rpy="0 0 0" xyz="0 0 0"/>
      <material name="white"/>
    </visual>
  </link>

  <joint name="base_to_wheel_back_right" type="continuous">
    <parent link="base_link"/>
    <child link="wheel_back_right"/>
    <origin xyz="-0.35 -0.4 0.0" rpy="1.5707 0 0"/>
    <axis xyz="0 0 1"/>
  </joint>

  <link name="wheel_front_left">
    <visual>
      <geometry>
        <cylinder length="0.13" radius="0.25"/>
      </geometry>
      <origin rpy="0 0 0" xyz="0 0 0"/>
      <material name="white"/>
    </visual>
  </link>

  <joint name="base_to_wheel_front_left" type="continuous">
    <parent link="base_link"/>
    <child link="wheel_front_left"/>
    <origin xyz="1.55 0.4 0.0" rpy="-1.5707 0 0"/>
    <axis xyz="0 0 1"/>
  </joint>

  <link name="wheel_front_right">
    <visual>
      <geometry>
        <cylinder length="0.13" radius="0.25"/>
      </geometry>
      <origin rpy="0 0 0" xyz="0 0 0"/>
      <material name="white"/>
    </visual>
  </link>

  <joint name="base_to_wheel_front_right" type="continuous">
    <parent link="base_link"/>
    <child link="wheel_front_right"/>
    <origin xyz="1.55 -0.4 0.0" rpy="1.5707 0 0"/>
    <axis xyz="0 0 1"/>
  </joint>

  <!--WHEELS-->
  <!--WHEELS-->
  <!--WHEELS-->

  <!-- CAMERA 0 0 -->
  <link name="camera_0_0">
    <visual>
      <geometry>
        <box size="0.025 0.025 0.025"/>
      </geometry>
      <origin rpy="0 0 0" xyz="0 0 0.025"/>
      <material name="red"/>
    </visual>
  </link>
  <!-- Currently from velodyne, should fix!-->
  <joint name="base_to_camera_0_0" type="fixed">
    <parent link="velodyne"/>
    <child link="camera_0_0"/>
    <origin xyz="0.71952893 0.18228876 -0.11169658" rpy="-1.66591346 0.02767927 -1.56243623"/>
  </joint>


  <!-- CAMERA 0 1 -->
  <link name="camera_0_1">
    <visual>
      <geometry>
        <box size="0.025 0.025 0.025"/>
      </geometry>
      <origin rpy="0 0 0" xyz="0 0 0.025"/>
      <material name="red"/>
    </visual>
  </link>
  <!-- Currently from velodyne, should fix!-->
  <joint name="base_to_camera_0_1" type="fixed">
    <parent link="velodyne"/>
    <child link="camera_0_1"/>
    <origin xyz="0.72892175 -0.05673481 -0.11099091" rpy="-1.67188418 -0.01535144 -1.58131909"/>
  </joint>

    <!-- CAMERA 0 2 -->
  <link name="camera_0_2">
    <visual>
      <geometry>
        <box size="0.025 0.025 0.025"/>
      </geometry>
      <origin rpy="0 0 0" xyz="0 0 0.025"/>
      <material name="red"/>
    </visual>
  </link>
  <!-- Currently from velodyne, should fix!-->
  <joint name="base_to_camera_0_2" type="fixed">
    <parent link="velodyne"/>
    <child link="camera_0_2"/>
    <origin xyz="0.71595247 0.04320704 -0.10889413" rpy="-1.62651831 0.01519602 -1.58760043"/>
  </joint>

      <!-- CAMERA 0 3 -->
  <link name="camera_0_3">
    <visual>
      <geometry>
        <box size="0.025 0.025 0.025"/>
      </geometry>
      <origin rpy="0 0 0" xyz="0 0 0.025"/>
      <material name="red"/>
    </visual>
  </link>
  <!-- Currently from velodyne, should fix!-->
  <joint name="base_to_camera_0_3" type="fixed">
    <parent link="velodyne"/>
    <child link="camera_0_3"/>
    <origin xyz="-0.0694195 -0.3498999 -0.24136454" rpy="-1.96808264 0.00685974 -2.72363733"/>
  </joint>




      <!-- CAMERA 1 0 -->
  <link name="camera_1_0">
    <visual>
      <geometry>
        <box size="0.025 0.025 0.025"/>
      </geometry>
      <origin rpy="0 0 0" xyz="0 0 0.025"/>
      <material name="red"/>
    </visual>
  </link>
  <!-- Currently from velodyne, should fix!-->
  <joint name="base_to_camera_1_0" type="fixed">
    <parent link="velodyne"/>
    <child link="camera_1_0"/>
    <origin xyz="-0.16464988 -0.34072625 -0.24120047" rpy="-1.98093700 -0.01411756 2.52344939"/>
  </joint>

      <!-- CAMERA 1 1 -->
  <link name="camera_1_1">
    <visual>
      <geometry>
        <box size="0.025 0.025 0.025"/>
      </geometry>
      <origin rpy="0 0 0" xyz="0 0 0.025"/>
      <material name="red"/>
    </visual>
  </link>
  <!-- Currently from velodyne, should fix!-->
  <joint name="base_to_camera_1_1" type="fixed">
    <parent link="velodyne"/>
    <child link="camera_1_1"/>
    <origin xyz="-0.16035341 0.40248961 -0.2399301" rpy="-1.95964227 -0.00265567 0.65826705"/>
  </joint>

        <!-- CAMERA 1 2 -->
  <link name="camera_1_2">
    <visual>
      <geometry>
        <box size="0.025 0.025 0.025"/>
      </geometry>
      <origin rpy="0 0 0" xyz="0 0 0.025"/>
      <material name="red"/>
    </visual>
  </link>
  <!-- Currently from velodyne, should fix!-->
  <joint name="base_to_camera_1_2" type="fixed">
    <parent link="velodyne"/>
    <child link="camera_1_2"/>
    <origin xyz="-0.08410137 0.41974232 -0.23364842" rpy="-1.94080217 -0.01932027 -0.41554672"/>
  </joint>

        <!-- CAMERA 1 3 -->
  <link name="camera_1_3">
    <visual>
      <geometry>
        <box size="0.025 0.025 0.025"/>
      </geometry>
      <origin rpy="0 0 0" xyz="0 0 0.025"/>
      <material name="red"/>
    </visual>
  </link>
  <!-- Currently from velodyne, should fix!-->
  <joint name="base_to_camera_1_3" type="fixed">
    <parent link="velodyne"/>
    <child link="camera_1_3"/>
    <origin xyz="-0.36160303 0.02466039 -0.15475114" rpy="-1.93504084 -0.00216531 1.57051568"/>
  </joint>

</robot>
